2025-03-04 14:32:05,042 INFO    MainThread:34930 [internal.py:wandb_internal():90] W&B internal server running at pid: 34930, started at: 2025-03-04 14:32:05.041863
2025-03-04 14:32:05,043 INFO    WriterThread:34930 [datastore.py:open_for_write():75] open: /Users/patmccarthy/Documents/ThalamoCortex/train_scripts/wandb/run-20250304_143203-s0xoham6/run-s0xoham6.wandb
2025-03-04 14:32:05,045 DEBUG   SenderThread:34930 [sender.py:send():236] send: header
2025-03-04 14:32:05,046 DEBUG   SenderThread:34930 [sender.py:send():236] send: run
2025-03-04 14:32:05,208 ERROR   SenderThread:34930 [internal_api.py:execute():161] 404 response executing GraphQL.
2025-03-04 14:32:05,208 ERROR   SenderThread:34930 [internal_api.py:execute():162] {"errors":[{"message":"entity my-awesome-team-name not found during upsertBucket","path":["upsertBucket"]}],"data":{"upsertBucket":null}}
2025-03-04 14:32:06,044 INFO    HandlerThread:34930 [handler.py:finish():806] shutting down handler
2025-03-04 14:32:06,047 INFO    WriterThread:34930 [datastore.py:close():279] close: /Users/patmccarthy/Documents/ThalamoCortex/train_scripts/wandb/run-20250304_143203-s0xoham6/run-s0xoham6.wandb
2025-03-04 14:32:06,048 ERROR   MainThread:34930 [internal.py:wandb_internal():165] Thread SenderThread:
Traceback (most recent call last):
  File "/Users/patmccarthy/miniconda3/envs/thalamocortex/lib/python3.10/site-packages/wandb/sdk/lib/retry.py", line 108, in __call__
    result = self._call_fn(*args, **kwargs)
  File "/Users/patmccarthy/miniconda3/envs/thalamocortex/lib/python3.10/site-packages/wandb/sdk/internal/internal_api.py", line 158, in execute
    return self.client.execute(*args, **kwargs)
  File "/Users/patmccarthy/miniconda3/envs/thalamocortex/lib/python3.10/site-packages/wandb/vendor/gql-0.2.0/wandb_gql/client.py", line 52, in execute
    result = self._get_result(document, *args, **kwargs)
  File "/Users/patmccarthy/miniconda3/envs/thalamocortex/lib/python3.10/site-packages/wandb/vendor/gql-0.2.0/wandb_gql/client.py", line 60, in _get_result
    return self.transport.execute(document, *args, **kwargs)
  File "/Users/patmccarthy/miniconda3/envs/thalamocortex/lib/python3.10/site-packages/wandb/vendor/gql-0.2.0/wandb_gql/transport/requests.py", line 39, in execute
    request.raise_for_status()
  File "/Users/patmccarthy/miniconda3/envs/thalamocortex/lib/python3.10/site-packages/requests/models.py", line 1024, in raise_for_status
    raise HTTPError(http_error_msg, response=self)
requests.exceptions.HTTPError: 404 Client Error: Not Found for url: https://api.wandb.ai/graphql

During handling of the above exception, another exception occurred:

Traceback (most recent call last):
  File "/Users/patmccarthy/miniconda3/envs/thalamocortex/lib/python3.10/site-packages/wandb/apis/normalize.py", line 25, in wrapper
    return func(*args, **kwargs)
  File "/Users/patmccarthy/miniconda3/envs/thalamocortex/lib/python3.10/site-packages/wandb/sdk/internal/internal_api.py", line 1341, in upsert_run
    response = self.gql(mutation, variable_values=variable_values, **kwargs)
  File "/Users/patmccarthy/miniconda3/envs/thalamocortex/lib/python3.10/site-packages/wandb/sdk/lib/retry.py", line 124, in __call__
    if not check_retry_fn(e):
  File "/Users/patmccarthy/miniconda3/envs/thalamocortex/lib/python3.10/site-packages/wandb/util.py", line 887, in no_retry_auth
    raise CommError("Permission denied, ask the project owner to grant you access")
wandb.errors.CommError: Permission denied, ask the project owner to grant you access

During handling of the above exception, another exception occurred:

Traceback (most recent call last):
  File "/Users/patmccarthy/miniconda3/envs/thalamocortex/lib/python3.10/site-packages/wandb/sdk/internal/internal_util.py", line 51, in run
    self._run()
  File "/Users/patmccarthy/miniconda3/envs/thalamocortex/lib/python3.10/site-packages/wandb/sdk/internal/internal_util.py", line 102, in _run
    self._process(record)
  File "/Users/patmccarthy/miniconda3/envs/thalamocortex/lib/python3.10/site-packages/wandb/sdk/internal/internal.py", line 310, in _process
    self._sm.send(record)
  File "/Users/patmccarthy/miniconda3/envs/thalamocortex/lib/python3.10/site-packages/wandb/sdk/internal/sender.py", line 238, in send
    send_handler(record)
  File "/Users/patmccarthy/miniconda3/envs/thalamocortex/lib/python3.10/site-packages/wandb/sdk/internal/sender.py", line 696, in send_run
    self._init_run(run, config_value_dict)
  File "/Users/patmccarthy/miniconda3/envs/thalamocortex/lib/python3.10/site-packages/wandb/sdk/internal/sender.py", line 720, in _init_run
    server_run, inserted = self._api.upsert_run(
  File "/Users/patmccarthy/miniconda3/envs/thalamocortex/lib/python3.10/site-packages/wandb/apis/normalize.py", line 61, in wrapper
    raise CommError(message, err).with_traceback(sys.exc_info()[2])
  File "/Users/patmccarthy/miniconda3/envs/thalamocortex/lib/python3.10/site-packages/wandb/apis/normalize.py", line 25, in wrapper
    return func(*args, **kwargs)
  File "/Users/patmccarthy/miniconda3/envs/thalamocortex/lib/python3.10/site-packages/wandb/sdk/internal/internal_api.py", line 1341, in upsert_run
    response = self.gql(mutation, variable_values=variable_values, **kwargs)
  File "/Users/patmccarthy/miniconda3/envs/thalamocortex/lib/python3.10/site-packages/wandb/sdk/lib/retry.py", line 124, in __call__
    if not check_retry_fn(e):
  File "/Users/patmccarthy/miniconda3/envs/thalamocortex/lib/python3.10/site-packages/wandb/util.py", line 887, in no_retry_auth
    raise CommError("Permission denied, ask the project owner to grant you access")
wandb.errors.CommError: Permission denied, ask the project owner to grant you access
2025-03-04 14:32:08,089 INFO    MainThread:34930 [internal.py:handle_exit():80] Internal process exited
